Traceback (most recent call last):
  File "/Users/billydodds/.pyenv/versions/3.8.3/envs/phys/lib/python3.8/site-packages/jupyter_cache/executors/utils.py", line 51, in single_nb_execution
    executenb(
  File "/Users/billydodds/.pyenv/versions/3.8.3/envs/phys/lib/python3.8/site-packages/nbclient/client.py", line 1112, in execute
    return NotebookClient(nb=nb, resources=resources, km=km, **kwargs).execute()
  File "/Users/billydodds/.pyenv/versions/3.8.3/envs/phys/lib/python3.8/site-packages/nbclient/util.py", line 74, in wrapped
    return just_run(coro(*args, **kwargs))
  File "/Users/billydodds/.pyenv/versions/3.8.3/envs/phys/lib/python3.8/site-packages/nbclient/util.py", line 53, in just_run
    return loop.run_until_complete(coro)
  File "/Users/billydodds/.pyenv/versions/3.8.3/lib/python3.8/asyncio/base_events.py", line 616, in run_until_complete
    return future.result()
  File "/Users/billydodds/.pyenv/versions/3.8.3/envs/phys/lib/python3.8/site-packages/nbclient/client.py", line 553, in async_execute
    await self.async_execute_cell(
  File "/Users/billydodds/.pyenv/versions/3.8.3/envs/phys/lib/python3.8/site-packages/nbclient/client.py", line 857, in async_execute_cell
    self._check_raise_for_error(cell, exec_reply)
  File "/Users/billydodds/.pyenv/versions/3.8.3/envs/phys/lib/python3.8/site-packages/nbclient/client.py", line 760, in _check_raise_for_error
    raise CellExecutionError.from_cell_and_msg(cell, exec_reply_content)
nbclient.exceptions.CellExecutionError: An error occurred while executing the following cell:
------------------
# Final classifier used for Space Invaders

# Connect to spiker box - change to match port
cport = "/dev/cu.usbserial-DJ00E33Q"
baudrate = 230400
ser = serial.Serial(port=cport, baudrate=baudrate)    
inputBufferSize = 1000   # 20000 = 1 second
buffer_size_sec = inputBufferSize/20000.0
ser.timeout = buffer_size_sec  # set read timeout 20000

classifier_label = "Max-Min-Range"
offset = (optimal_cl_windows[classifier_label] - opt_det_window)/2
buffer_size = 0.05
streaming_classifier(
    ser,
    samprate,
    classifiers[classifier_label],
    classifier_params=classifier_parameters[classifier_label],
    input_buffer_size_sec = buffer_size_sec,
    classification_window_size_sec = optimal_cl_windows[classifier_label],
    detection_window_size_sec = opt_det_window,
    detection_window_offset_sec = offset,
    calibration_window_size_sec = calibration_window_sec,
    calibration_statistic_function = lambda x: ts_zero_crossings(x)/len(x),
    event_test_statistic_function = lambda x: ts_zero_crossings(x)/len(x), 
    event_threshold_factor = opt_thresh, 
    flip_threshold = True, 
    consecutive_event_triggers = 3, 
    consecutive_nonevent_reset = 10,
    live = True,
    FIFO_filename = "space_invaders_ipc",
    create_FIFO_msg = None,
    )

------------------

[0;31m---------------------------------------------------------------------------[0m
[0;31mFileNotFoundError[0m                         Traceback (most recent call last)
[0;32m~/.pyenv/versions/3.8.3/envs/phys/lib/python3.8/site-packages/serial/serialposix.py[0m in [0;36mopen[0;34m(self)[0m
[1;32m    321[0m         [0;32mtry[0m[0;34m:[0m[0;34m[0m[0;34m[0m[0m
[0;32m--> 322[0;31m             [0mself[0m[0;34m.[0m[0mfd[0m [0;34m=[0m [0mos[0m[0;34m.[0m[0mopen[0m[0;34m([0m[0mself[0m[0;34m.[0m[0mportstr[0m[0;34m,[0m [0mos[0m[0;34m.[0m[0mO_RDWR[0m [0;34m|[0m [0mos[0m[0;34m.[0m[0mO_NOCTTY[0m [0;34m|[0m [0mos[0m[0;34m.[0m[0mO_NONBLOCK[0m[0;34m)[0m[0;34m[0m[0;34m[0m[0m
[0m[1;32m    323[0m         [0;32mexcept[0m [0mOSError[0m [0;32mas[0m [0mmsg[0m[0;34m:[0m[0;34m[0m[0;34m[0m[0m

[0;31mFileNotFoundError[0m: [Errno 2] No such file or directory: '/dev/cu.usbserial-DJ00E33Q'

During handling of the above exception, another exception occurred:

[0;31mSerialException[0m                           Traceback (most recent call last)
[0;32m<ipython-input-21-994ec2ec03df>[0m in [0;36m<module>[0;34m[0m
[1;32m      4[0m [0mcport[0m [0;34m=[0m [0;34m"/dev/cu.usbserial-DJ00E33Q"[0m[0;34m[0m[0;34m[0m[0m
[1;32m      5[0m [0mbaudrate[0m [0;34m=[0m [0;36m230400[0m[0;34m[0m[0;34m[0m[0m
[0;32m----> 6[0;31m [0mser[0m [0;34m=[0m [0mserial[0m[0;34m.[0m[0mSerial[0m[0;34m([0m[0mport[0m[0;34m=[0m[0mcport[0m[0;34m,[0m [0mbaudrate[0m[0;34m=[0m[0mbaudrate[0m[0;34m)[0m[0;34m[0m[0;34m[0m[0m
[0m[1;32m      7[0m [0minputBufferSize[0m [0;34m=[0m [0;36m1000[0m   [0;31m# 20000 = 1 second[0m[0;34m[0m[0;34m[0m[0m
[1;32m      8[0m [0mbuffer_size_sec[0m [0;34m=[0m [0minputBufferSize[0m[0;34m/[0m[0;36m20000.0[0m[0;34m[0m[0;34m[0m[0m

[0;32m~/.pyenv/versions/3.8.3/envs/phys/lib/python3.8/site-packages/serial/serialutil.py[0m in [0;36m__init__[0;34m(self, port, baudrate, bytesize, parity, stopbits, timeout, xonxoff, rtscts, write_timeout, dsrdtr, inter_byte_timeout, exclusive, **kwargs)[0m
[1;32m    242[0m [0;34m[0m[0m
[1;32m    243[0m         [0;32mif[0m [0mport[0m [0;32mis[0m [0;32mnot[0m [0;32mNone[0m[0;34m:[0m[0;34m[0m[0;34m[0m[0m
[0;32m--> 244[0;31m             [0mself[0m[0;34m.[0m[0mopen[0m[0;34m([0m[0;34m)[0m[0;34m[0m[0;34m[0m[0m
[0m[1;32m    245[0m [0;34m[0m[0m
[1;32m    246[0m     [0;31m#  -  -  -  -  -  -  -  -  -  -  -  -  -  -  -  -  -  -  -  -  -  -  -  -[0m[0;34m[0m[0;34m[0m[0;34m[0m[0m

[0;32m~/.pyenv/versions/3.8.3/envs/phys/lib/python3.8/site-packages/serial/serialposix.py[0m in [0;36mopen[0;34m(self)[0m
[1;32m    323[0m         [0;32mexcept[0m [0mOSError[0m [0;32mas[0m [0mmsg[0m[0;34m:[0m[0;34m[0m[0;34m[0m[0m
[1;32m    324[0m             [0mself[0m[0;34m.[0m[0mfd[0m [0;34m=[0m [0;32mNone[0m[0;34m[0m[0;34m[0m[0m
[0;32m--> 325[0;31m             [0;32mraise[0m [0mSerialException[0m[0;34m([0m[0mmsg[0m[0;34m.[0m[0merrno[0m[0;34m,[0m [0;34m"could not open port {}: {}"[0m[0;34m.[0m[0mformat[0m[0;34m([0m[0mself[0m[0;34m.[0m[0m_port[0m[0;34m,[0m [0mmsg[0m[0;34m)[0m[0;34m)[0m[0;34m[0m[0;34m[0m[0m
[0m[1;32m    326[0m         [0;31m#~ fcntl.fcntl(self.fd, fcntl.F_SETFL, 0)  # set blocking[0m[0;34m[0m[0;34m[0m[0;34m[0m[0m
[1;32m    327[0m [0;34m[0m[0m

[0;31mSerialException[0m: [Errno 2] could not open port /dev/cu.usbserial-DJ00E33Q: [Errno 2] No such file or directory: '/dev/cu.usbserial-DJ00E33Q'
SerialException: [Errno 2] could not open port /dev/cu.usbserial-DJ00E33Q: [Errno 2] No such file or directory: '/dev/cu.usbserial-DJ00E33Q'

